<?xml version="1.0" encoding="utf-8"?>
<!-- =================================================================================== -->
<!-- |    This document was autogenerated by xacro from robot.xacro                    | -->
<!-- |    EDITING THIS FILE BY HAND IS NOT RECOMMENDED                                 | -->
<!-- =================================================================================== -->
<robot name="manipulator">
  <!-- Joints and Links Names-->
  <!-- Parameters that you can change-->
  <!-- link 9 the same as 8-->
  <!-- Base link - box-->
  <!-- Definition and Geometry of world frame-->
  <link name="world_link"/>
  <!-- zero_joint -->
  <joint name="zero_joint" type="fixed">
    <origin rpy="0 0 0" xyz="0 0 0"/>
    <parent link="world_link"/>
    <child link="base_link"/>
  </joint>
  <!-- Definition and Geometry of base link-->
  <link name="base_link">
    <visual>
      <origin rpy="0 0 0" xyz="0 0 0.05"/>
      <geometry>
        <box size="1 1 0.1"/>
      </geometry>
      <!-- Material and color of 0 -->
      <material name="blue">
        <color rgba="0 0 0.8 1"/>
      </material>
    </visual>
    <collision>
      <origin rpy="0 0 0" xyz="0 0 0"/>
      <geometry>
        <box size="1 1 0.1"/>
      </geometry>
    </collision>
    <inertial>
      <mass value="1000"/>
      <inertia ixx="1.0" ixy="0.0" ixz="0.0" iyy="0.5" iyz="0.0" izz="1.0"/>
    </inertial>
    <!-- -                         -->
  </link>
  <!-- JOINT 1 -->
  <joint name="first_joint" type="revolute">
    <origin rpy="0 0 0" xyz="0 0 0.1"/>
    <parent link="base_link"/>
    <child link="first_link"/>
    <axis xyz="0 0 1"/>
    <limit effort="1000" lower="-1.57079632679" upper="1.57079632679" velocity="1"/>
  </joint>
  <transmission name="tran1">
    <type>transmission_interface/SimpleTransmission</type>
    <joint name="first_joint">
      <hardwareInterface>hardware_interface/EffortJointInterface</hardwareInterface>
    </joint>
    <actuator name="motor1">
      <hardwareInterface>hardware_interface/EffortJointInterface</hardwareInterface>
      <mechanicalReduction>1</mechanicalReduction>
    </actuator>
  </transmission>
  <!-- Definition and Geometry of FIRST 1  link-->
  <link name="first_link">
    <visual>
      <origin rpy="0 0 0" xyz="0 0 0.25"/>
      <geometry>
        <cylinder length="0.5" radius="0.2"/>
      </geometry>
      <!-- Material and color of 1st -->
      <material name="red">
        <color rgba="0.8 0 0 1"/>
      </material>
    </visual>
    <collision>
      <origin rpy="0 0 0" xyz="0 0 0.25"/>
      <geometry>
        <cylinder length="0.5" radius="0.2"/>
      </geometry>
    </collision>
    <inertial>
      <mass value="100"/>
      <inertia ixx="1.0" ixy="0.0" ixz="0.0" iyy="0.5" iyz="0.0" izz="1.0"/>
    </inertial>
  </link>
  <!-- JOINT 2 -->
  <joint name="second_joint" type="prismatic">
    <origin rpy="0 0 0" xyz="0 0 0.5"/>
    <parent link="first_link"/>
    <child link="second_link"/>
    <axis xyz="0 0 1"/>
    <limit effort="100" lower="0" upper="0.4" velocity="0.5"/>
  </joint>
  <!-- Definition and Geometry of SECOND 2 link-->
  <link name="second_link">
    <visual>
      <origin rpy="0 0 0" xyz="0 0 -0.1"/>
      <geometry>
        <box size="0.2 0.2 0.8"/>
      </geometry>
      <!-- Material and color of 2st -->
      <material name="green">
        <color rgba="0 0.8 0 1"/>
      </material>
    </visual>
    <collision>
      <origin rpy="0 0 0" xyz="0 0 -0.1"/>
      <geometry>
        <box size="0.2 0.2 0.8"/>
      </geometry>
    </collision>
    <inertial>
      <mass value="50"/>
      <inertia ixx="1.0" ixy="0.0" ixz="0.0" iyy="0.5" iyz="0.0" izz="1.0"/>
    </inertial>
  </link>
  <!-- JOINT 3 -->
  <joint name="third_joint" type="revolute">
    <origin rpy="-1.0471975512 0 0" xyz="0 0 0.3"/>
    <parent link="second_link"/>
    <child link="third_link"/>
    <axis xyz="1 0 0"/>
    <limit effort="0" lower="-0.785398163397" upper="0.785398163397" velocity="0.5"/>
  </joint>
  <!-- Definition and Geometry of THIRD 3 link-->
  <link name="third_link">
    <visual>
      <origin rpy="0 0 0" xyz="0 0 0.3"/>
      <geometry>
        <cylinder length="0.6" radius="0.075"/>
      </geometry>
      <!-- Material and color of 3st -->
      <material name="yellow">
        <color rgba="0.9 0.9 0 1"/>
      </material>
    </visual>
    <collision>
      <origin rpy="0 0 0" xyz="0 0 0.3"/>
      <geometry>
        <cylinder length="0.6" radius="0.075"/>
      </geometry>
    </collision>
    <inertial>
      <mass value="20"/>
      <inertia ixx="1.0" ixy="0.0" ixz="0.0" iyy="0.5" iyz="0.0" izz="1.0"/>
    </inertial>
  </link>
  <!-- JOINT 4 -->
  <joint name="fourth_joint" type="revolute">
    <origin rpy="-2.09439510239 0 0" xyz="0 0 0.6"/>
    <parent link="third_link"/>
    <child link="fourth_link"/>
    <axis xyz="1 0 0"/>
    <limit effort="0" lower="0" upper="3.14159265359" velocity="0.5"/>
  </joint>
  <!-- Definition and Geometry of FOURTH 4 link-->
  <link name="fourth_link">
    <visual>
      <origin rpy="0 0 0" xyz="0 0 0.125"/>
      <geometry>
        <cylinder length="0.25" radius="0.05"/>
      </geometry>
      <!-- Material and color of 4st -->
      <material name="grey">
        <color rgba="0.9 0.9 0.9 1"/>
      </material>
    </visual>
    <collision>
      <origin rpy="0 0 0" xyz="0 0 0.125"/>
      <geometry>
        <cylinder length="0.25" radius="0.05"/>
      </geometry>
    </collision>
    <inertial>
      <mass value="10"/>
      <inertia ixx="1.0" ixy="0.0" ixz="0.0" iyy="0.5" iyz="0.0" izz="1.0"/>
    </inertial>
  </link>
  <!-- JOINT 5 -->
  <joint name="fifth_joint" type="revolute">
    <origin rpy="0 0 0" xyz="0 0 0.25"/>
    <parent link="fourth_link"/>
    <child link="fifth_link"/>
    <axis xyz="0 0 1"/>
    <limit effort="0" lower="-1.57079632679" upper="1.57079632679" velocity="1"/>
  </joint>
  <!-- Definition and Geometry of FIFTH 5 link-->
  <link name="fifth_link">
    <visual>
      <origin rpy="0 0 0" xyz="0 0 0.05"/>
      <geometry>
        <cylinder length="0.1" radius="0.03"/>
      </geometry>
      <!-- Material and color of 5st -->
      <material name="white">
        <color rgba="1 1 1 1"/>
      </material>
    </visual>
    <collision>
      <origin rpy="0 0 0" xyz="0 0 0.05"/>
      <geometry>
        <cylinder length="0.1" radius="0.03"/>
      </geometry>
    </collision>
    <inertial>
      <mass value="4"/>
      <inertia ixx="1.0" ixy="0.0" ixz="0.0" iyy="0.5" iyz="0.0" izz="1.0"/>
    </inertial>
  </link>
  <!-- JOINT 6 -->
  <joint name="sixth_joint" type="revolute">
    <origin rpy="1.57079632679 0 0" xyz="0 0 0.1"/>
    <parent link="fifth_link"/>
    <child link="sixth_link"/>
    <axis xyz="1 0 0"/>
    <limit effort="0" lower="-3.14159265359" upper="0" velocity="1"/>
  </joint>
  <!-- Definition and Geometry of SIXTH 6 link-->
  <link name="sixth_link">
    <visual>
      <origin rpy="0 0 0" xyz="0 0 0.075"/>
      <geometry>
        <cylinder length="0.15" radius="0.02"/>
      </geometry>
      <!-- Material and color of 6st -->
      <material name="purple">
        <color rgba="0.64 0.05 0.97 1"/>
      </material>
    </visual>
    <collision>
      <origin rpy="0 0 0" xyz="0 0 0.075"/>
      <geometry>
        <cylinder length="0.15" radius="0.02"/>
      </geometry>
    </collision>
    <inertial>
      <mass value="2"/>
      <inertia ixx="1.0" ixy="0.0" ixz="0.0" iyy="0.5" iyz="0.0" izz="1.0"/>
    </inertial>
  </link>
  <!-- JOINT 7 -->
  <joint name="seventh_joint" type="fixed">
    <origin rpy="0 1.57079632679 0" xyz="0 0 0.15"/>
    <parent link="sixth_link"/>
    <child link="seventh_link"/>
  </joint>
  <!-- Definition and Geometry of SEVENTH 7 link-->
  <link name="seventh_link">
    <visual>
      <origin rpy="0 0 0" xyz="0 0 0"/>
      <geometry>
        <cylinder length="0.15" radius="0.02"/>
      </geometry>
      <!-- Material and color of 7 -->
      <material name="purple">
        <color rgba="0.64 0.05 0.97 1"/>
      </material>
    </visual>
    <collision>
      <origin rpy="0 0 0" xyz="0 0 0"/>
      <geometry>
        <cylinder length="0.15" radius="0.02"/>
      </geometry>
    </collision>
    <inertial>
      <mass value="1"/>
      <inertia ixx="1.0" ixy="0.0" ixz="0.0" iyy="0.5" iyz="0.0" izz="1.0"/>
    </inertial>
  </link>
  <!-- JOINT 8 -->
  <joint name="eighth_joint" type="revolute">
    <origin rpy="0 -1.57079632679 0" xyz="0 0 0.075"/>
    <parent link="seventh_link"/>
    <child link="eighth_link"/>
    <axis xyz="0 1 0"/>
    <limit effort="0" lower="-0.523598775598" upper="0.523598775598" velocity="1"/>
  </joint>
  <!-- Definition and Geometry of SIXTH 8 link-->
  <link name="eighth_link">
    <visual>
      <origin rpy="0 0 0" xyz="0 0 0.05"/>
      <geometry>
        <cylinder length="0.1" radius="0.01"/>
      </geometry>
      <!-- Material and color of 8st -->
      <material name="yellow2">
        <color rgba="1 1 0 1"/>
      </material>
    </visual>
    <collision>
      <origin rpy="0 0 0" xyz="0 0 0.05"/>
      <geometry>
        <cylinder length="0.1" radius="0.01"/>
      </geometry>
    </collision>
    <inertial>
      <mass value="0.5"/>
      <inertia ixx="1.0" ixy="0.0" ixz="0.0" iyy="0.5" iyz="0.0" izz="1.0"/>
    </inertial>
  </link>
  <!-- JOINT 9 -->
  <joint name="nineth_joint" type="revolute">
    <origin rpy="0 -1.57079632679 0" xyz="0 0 -0.075"/>
    <parent link="seventh_link"/>
    <child link="nineth_link"/>
    <axis xyz="0 1 0"/>
    <limit effort="0" lower="-0.523598775598" upper="0.523598775598" velocity="1"/>
  </joint>
  <!-- Definition and Geometry of SIXTH 8 link-->
  <link name="nineth_link">
    <visual>
      <origin rpy="0 0 0" xyz="0 0 0.05"/>
      <geometry>
        <cylinder length="0.1" radius="0.01"/>
      </geometry>
      <!-- Material and color of 8st -->
      <material name="yellow2">
        <color rgba="1 1 0 1"/>
      </material>
    </visual>
    <collision>
      <origin rpy="0 0 0" xyz="0 0 0.05"/>
      <geometry>
        <cylinder length="0.1" radius="0.01"/>
      </geometry>
    </collision>
    <inertial>
      <mass value="0.5"/>
      <inertia ixx="1.0" ixy="0.0" ixz="0.0" iyy="0.5" iyz="0.0" izz="1.0"/>
    </inertial>
  </link>
  <gazebo>
    <plugin filename="libgazebo_ros_control.so" name="gazebo_ros_control">
      <robotNamespace>/manipulator</robotNamespace>
      <robotSimType>gazebo_ros_control/DefaultRobotHWSim</robotSimType>
    </plugin>
  </gazebo>
</robot>

